Traceback (most recent call last):
  File "/Users/kvarada/opt/miniconda3/envs/cpsc330/lib/python3.9/site-packages/jupyter_cache/executors/utils.py", line 51, in single_nb_execution
    executenb(
  File "/Users/kvarada/opt/miniconda3/envs/cpsc330/lib/python3.9/site-packages/nbclient/client.py", line 1117, in execute
    return NotebookClient(nb=nb, resources=resources, km=km, **kwargs).execute()
  File "/Users/kvarada/opt/miniconda3/envs/cpsc330/lib/python3.9/site-packages/nbclient/util.py", line 78, in wrapped
    return just_run(coro(*args, **kwargs))
  File "/Users/kvarada/opt/miniconda3/envs/cpsc330/lib/python3.9/site-packages/nbclient/util.py", line 57, in just_run
    return loop.run_until_complete(coro)
  File "/Users/kvarada/opt/miniconda3/envs/cpsc330/lib/python3.9/asyncio/base_events.py", line 642, in run_until_complete
    return future.result()
  File "/Users/kvarada/opt/miniconda3/envs/cpsc330/lib/python3.9/site-packages/nbclient/client.py", line 558, in async_execute
    await self.async_execute_cell(
  File "/Users/kvarada/opt/miniconda3/envs/cpsc330/lib/python3.9/site-packages/nbclient/client.py", line 862, in async_execute_cell
    self._check_raise_for_error(cell, exec_reply)
  File "/Users/kvarada/opt/miniconda3/envs/cpsc330/lib/python3.9/site-packages/nbclient/client.py", line 765, in _check_raise_for_error
    raise CellExecutionError.from_cell_and_msg(cell, exec_reply_content)
nbclient.exceptions.CellExecutionError: An error occurred while executing the following cell:
------------------
from PIL import Image

# Predict labels with associated probabilities for unseen images
images = glob.glob("data/test_images/*.*")
for image in images:
    img = Image.open(image)
    img.load()
    plt.imshow(img)
    plt.show()
    df = classify_image(img)
    print(df.to_string(index=False))
    print("--------------------------------------------------------------")
------------------

[0;31m---------------------------------------------------------------------------[0m
[0;31mFileNotFoundError[0m                         Traceback (most recent call last)
[0;32m/var/folders/80/kr9rkqfj4w78h49djkz8yy9r0000gp/T/ipykernel_8173/830629992.py[0m in [0;36m<module>[0;34m[0m
[1;32m      8[0m     [0mplt[0m[0;34m.[0m[0mimshow[0m[0;34m([0m[0mimg[0m[0;34m)[0m[0;34m[0m[0;34m[0m[0m
[1;32m      9[0m     [0mplt[0m[0;34m.[0m[0mshow[0m[0;34m([0m[0;34m)[0m[0;34m[0m[0;34m[0m[0m
[0;32m---> 10[0;31m     [0mdf[0m [0;34m=[0m [0mclassify_image[0m[0;34m([0m[0mimg[0m[0;34m)[0m[0;34m[0m[0;34m[0m[0m
[0m[1;32m     11[0m     [0mprint[0m[0;34m([0m[0mdf[0m[0;34m.[0m[0mto_string[0m[0;34m([0m[0mindex[0m[0;34m=[0m[0;32mFalse[0m[0;34m)[0m[0;34m)[0m[0;34m[0m[0;34m[0m[0m
[1;32m     12[0m     [0mprint[0m[0;34m([0m[0;34m"--------------------------------------------------------------"[0m[0;34m)[0m[0;34m[0m[0;34m[0m[0m

[0;32m~/CS/2021-22/330/cpsc330/lectures/code/./utils.py[0m in [0;36mclassify_image[0;34m(img, topn)[0m
[1;32m     28[0m                                      std=[0.229, 0.224, 0.225]),])
[1;32m     29[0m [0;34m[0m[0m
[0;32m---> 30[0;31m     [0;32mwith[0m [0mopen[0m[0;34m([0m[0;34m'data/imagenet_classes.txt'[0m[0;34m)[0m [0;32mas[0m [0mf[0m[0;34m:[0m[0;34m[0m[0;34m[0m[0m
[0m[1;32m     31[0m         [0mclasses[0m [0;34m=[0m [0;34m[[0m[0mline[0m[0;34m.[0m[0mstrip[0m[0;34m([0m[0;34m)[0m [0;32mfor[0m [0mline[0m [0;32min[0m [0mf[0m[0;34m.[0m[0mreadlines[0m[0;34m([0m[0;34m)[0m[0;34m][0m[0;34m[0m[0;34m[0m[0m
[1;32m     32[0m [0;34m[0m[0m

[0;31mFileNotFoundError[0m: [Errno 2] No such file or directory: 'data/imagenet_classes.txt'
FileNotFoundError: [Errno 2] No such file or directory: 'data/imagenet_classes.txt'

