Traceback (most recent call last):
  File "/Users/kvarada/opt/miniconda3/envs/cpsc330/lib/python3.9/site-packages/jupyter_cache/executors/utils.py", line 51, in single_nb_execution
    executenb(
  File "/Users/kvarada/opt/miniconda3/envs/cpsc330/lib/python3.9/site-packages/nbclient/client.py", line 1117, in execute
    return NotebookClient(nb=nb, resources=resources, km=km, **kwargs).execute()
  File "/Users/kvarada/opt/miniconda3/envs/cpsc330/lib/python3.9/site-packages/nbclient/util.py", line 78, in wrapped
    return just_run(coro(*args, **kwargs))
  File "/Users/kvarada/opt/miniconda3/envs/cpsc330/lib/python3.9/site-packages/nbclient/util.py", line 57, in just_run
    return loop.run_until_complete(coro)
  File "/Users/kvarada/opt/miniconda3/envs/cpsc330/lib/python3.9/asyncio/base_events.py", line 642, in run_until_complete
    return future.result()
  File "/Users/kvarada/opt/miniconda3/envs/cpsc330/lib/python3.9/site-packages/nbclient/client.py", line 558, in async_execute
    await self.async_execute_cell(
  File "/Users/kvarada/opt/miniconda3/envs/cpsc330/lib/python3.9/site-packages/nbclient/client.py", line 862, in async_execute_cell
    self._check_raise_for_error(cell, exec_reply)
  File "/Users/kvarada/opt/miniconda3/envs/cpsc330/lib/python3.9/site-packages/nbclient/client.py", line 765, in _check_raise_for_error
    raise CellExecutionError.from_cell_and_msg(cell, exec_reply_content)
nbclient.exceptions.CellExecutionError: An error occurred while executing the following cell:
------------------
# import the libraries
import os
import sys

import graphviz
import IPython
import matplotlib.pyplot as plt
import numpy as np
import pandas as pd
from IPython.display import HTML
from sklearn.model_selection import train_test_split

sys.path.append("code/.")
from plotting_functions import *

# Classifiers
from sklearn.tree import DecisionTreeClassifier, export_graphviz
from utils import *

%matplotlib inline

pd.set_option("display.max_colwidth", 200)
------------------

[0;31m---------------------------------------------------------------------------[0m
[0;31mModuleNotFoundError[0m                       Traceback (most recent call last)
[0;32m/var/folders/80/kr9rkqfj4w78h49djkz8yy9r0000gp/T/ipykernel_7629/4243764780.py[0m in [0;36m<module>[0;34m[0m
[1;32m     12[0m [0;34m[0m[0m
[1;32m     13[0m [0msys[0m[0;34m.[0m[0mpath[0m[0;34m.[0m[0mappend[0m[0;34m([0m[0;34m"code/."[0m[0;34m)[0m[0;34m[0m[0;34m[0m[0m
[0;32m---> 14[0;31m [0;32mfrom[0m [0mplotting_functions[0m [0;32mimport[0m [0;34m*[0m[0;34m[0m[0;34m[0m[0m
[0m[1;32m     15[0m [0;34m[0m[0m
[1;32m     16[0m [0;31m# Classifiers[0m[0;34m[0m[0;34m[0m[0;34m[0m[0m

[0;31mModuleNotFoundError[0m: No module named 'plotting_functions'
ModuleNotFoundError: No module named 'plotting_functions'

